/Library/Frameworks/Python.framework/Versions/3.12/lib/python3.12/site-packages/pydantic/_internal/_config.py:345: UserWarning: Valid config keys have changed in V2:
* 'orm_mode' has been renamed to 'from_attributes'
  warnings.warn(message, UserWarning)
Google credentials not configured; Google Sheets writes are disabled
INFO:     Started server process [79006]
INFO:     Waiting for application startup.
INFO:     Application startup complete.
INFO:     Uvicorn running on http://127.0.0.1:8000 (Press CTRL+C to quit)
INFO:     127.0.0.1:60327 - "GET /api/social/posts HTTP/1.1" 500 Internal Server Error
ERROR:    Exception in ASGI application
Traceback (most recent call last):
  File "/Library/Frameworks/Python.framework/Versions/3.12/lib/python3.12/site-packages/uvicorn/protocols/http/httptools_impl.py", line 409, in run_asgi
    result = await app(  # type: ignore[func-returns-value]
             ^^^^^^^^^^^^^^^^^^^^^^^^^^^^^^^^^^^^^^^^^^^^^^
  File "/Library/Frameworks/Python.framework/Versions/3.12/lib/python3.12/site-packages/uvicorn/middleware/proxy_headers.py", line 60, in __call__
    return await self.app(scope, receive, send)
           ^^^^^^^^^^^^^^^^^^^^^^^^^^^^^^^^^^^^
  File "/Library/Frameworks/Python.framework/Versions/3.12/lib/python3.12/site-packages/fastapi/applications.py", line 1054, in __call__
    await super().__call__(scope, receive, send)
  File "/Library/Frameworks/Python.framework/Versions/3.12/lib/python3.12/site-packages/starlette/applications.py", line 112, in __call__
    await self.middleware_stack(scope, receive, send)
  File "/Library/Frameworks/Python.framework/Versions/3.12/lib/python3.12/site-packages/starlette/middleware/errors.py", line 187, in __call__
    raise exc
  File "/Library/Frameworks/Python.framework/Versions/3.12/lib/python3.12/site-packages/starlette/middleware/errors.py", line 165, in __call__
    await self.app(scope, receive, _send)
  File "/Library/Frameworks/Python.framework/Versions/3.12/lib/python3.12/site-packages/starlette/middleware/cors.py", line 85, in __call__
    await self.app(scope, receive, send)
  File "/Library/Frameworks/Python.framework/Versions/3.12/lib/python3.12/site-packages/starlette/middleware/exceptions.py", line 62, in __call__
    await wrap_app_handling_exceptions(self.app, conn)(scope, receive, send)
  File "/Library/Frameworks/Python.framework/Versions/3.12/lib/python3.12/site-packages/starlette/_exception_handler.py", line 53, in wrapped_app
    raise exc
  File "/Library/Frameworks/Python.framework/Versions/3.12/lib/python3.12/site-packages/starlette/_exception_handler.py", line 42, in wrapped_app
    await app(scope, receive, sender)
  File "/Library/Frameworks/Python.framework/Versions/3.12/lib/python3.12/site-packages/starlette/routing.py", line 714, in __call__
    await self.middleware_stack(scope, receive, send)
  File "/Library/Frameworks/Python.framework/Versions/3.12/lib/python3.12/site-packages/starlette/routing.py", line 734, in app
    await route.handle(scope, receive, send)
  File "/Library/Frameworks/Python.framework/Versions/3.12/lib/python3.12/site-packages/starlette/routing.py", line 288, in handle
    await self.app(scope, receive, send)
  File "/Library/Frameworks/Python.framework/Versions/3.12/lib/python3.12/site-packages/starlette/routing.py", line 76, in app
    await wrap_app_handling_exceptions(app, request)(scope, receive, send)
  File "/Library/Frameworks/Python.framework/Versions/3.12/lib/python3.12/site-packages/starlette/_exception_handler.py", line 53, in wrapped_app
    raise exc
  File "/Library/Frameworks/Python.framework/Versions/3.12/lib/python3.12/site-packages/starlette/_exception_handler.py", line 42, in wrapped_app
    await app(scope, receive, sender)
  File "/Library/Frameworks/Python.framework/Versions/3.12/lib/python3.12/site-packages/starlette/routing.py", line 73, in app
    response = await f(request)
               ^^^^^^^^^^^^^^^^
  File "/Library/Frameworks/Python.framework/Versions/3.12/lib/python3.12/site-packages/fastapi/routing.py", line 301, in app
    raw_response = await run_endpoint_function(
                   ^^^^^^^^^^^^^^^^^^^^^^^^^^^^
  File "/Library/Frameworks/Python.framework/Versions/3.12/lib/python3.12/site-packages/fastapi/routing.py", line 212, in run_endpoint_function
    return await dependant.call(**values)
           ^^^^^^^^^^^^^^^^^^^^^^^^^^^^^^
  File "/Users/jackffox/Desktop/street-meat-gatherings-unite/backend/routes/social_feed.py", line 47, in get_posts
    post_data = PostWithLikeStatus.model_validate(post)
                ^^^^^^^^^^^^^^^^^^^^^^^^^^^^^^^^^^^^^^^
  File "/Library/Frameworks/Python.framework/Versions/3.12/lib/python3.12/site-packages/pydantic/main.py", line 627, in model_validate
    return cls.__pydantic_validator__.validate_python(
           ^^^^^^^^^^^^^^^^^^^^^^^^^^^^^^^^^^^^^^^^^^^
pydantic_core._pydantic_core.ValidationError: 4 validation errors for PostWithLikeStatus
comments.0.likes_count
  Error extracting attribute: MissingGreenlet: greenlet_spawn has not been called; can't call await_only() here. Was IO attempted in an unexpected place? (Background on this error at: https://sqlalche.me/e/20/xd2s) [type=get_attribute_error, input_value=<backend.models.Comment object at 0x113acb980>, input_type=Comment]
    For further information visit https://errors.pydantic.dev/2.10/v/get_attribute_error
comments.0.replies
  Error extracting attribute: MissingGreenlet: greenlet_spawn has not been called; can't call await_only() here. Was IO attempted in an unexpected place? (Background on this error at: https://sqlalche.me/e/20/xd2s) [type=get_attribute_error, input_value=<backend.models.Comment object at 0x113acb980>, input_type=Comment]
    For further information visit https://errors.pydantic.dev/2.10/v/get_attribute_error
comments.1.likes_count
  Error extracting attribute: MissingGreenlet: greenlet_spawn has not been called; can't call await_only() here. Was IO attempted in an unexpected place? (Background on this error at: https://sqlalche.me/e/20/xd2s) [type=get_attribute_error, input_value=<backend.models.Comment object at 0x113acb9b0>, input_type=Comment]
    For further information visit https://errors.pydantic.dev/2.10/v/get_attribute_error
comments.1.replies
  Error extracting attribute: MissingGreenlet: greenlet_spawn has not been called; can't call await_only() here. Was IO attempted in an unexpected place? (Background on this error at: https://sqlalche.me/e/20/xd2s) [type=get_attribute_error, input_value=<backend.models.Comment object at 0x113acb9b0>, input_type=Comment]
    For further information visit https://errors.pydantic.dev/2.10/v/get_attribute_error
INFO:     127.0.0.1:60395 - "GET /api/auth/me HTTP/1.1" 200 OK
INFO:     127.0.0.1:60398 - "GET /api/auth/pickup-locations HTTP/1.1" 200 OK
INFO:     127.0.0.1:60401 - "GET /api/social/posts?location_filter=White+Plaza HTTP/1.1" 200 OK
INFO:     127.0.0.1:60404 - "GET /api/social/posts?location_filter=White+Plaza HTTP/1.1" 200 OK
INFO:     127.0.0.1:60411 - "GET /api/auth/me HTTP/1.1" 200 OK
INFO:     127.0.0.1:60414 - "GET /api/auth/pickup-locations HTTP/1.1" 200 OK
INFO:     127.0.0.1:60417 - "GET /api/social/posts?location_filter=Sigma+Nu HTTP/1.1" 200 OK
INFO:     127.0.0.1:60420 - "GET /api/social/posts?location_filter=Sigma+Nu HTTP/1.1" 200 OK
INFO:     127.0.0.1:60428 - "POST /api/social/user-profile-post/1?location=Kappa%20Sigma HTTP/1.1" 200 OK
INFO:     127.0.0.1:60429 - "GET /api/auth/me HTTP/1.1" 200 OK
INFO:     127.0.0.1:60432 - "GET /api/auth/pickup-locations HTTP/1.1" 200 OK
INFO:     127.0.0.1:60435 - "GET /api/social/posts?location_filter=Kappa+Sigma HTTP/1.1" 200 OK
INFO:     127.0.0.1:60439 - "GET /api/social/posts?location_filter=Kappa+Sigma HTTP/1.1" 200 OK
INFO:     127.0.0.1:60448 - "GET /api/auth/me HTTP/1.1" 200 OK
INFO:     127.0.0.1:60451 - "GET /api/auth/pickup-locations HTTP/1.1" 200 OK
INFO:     127.0.0.1:60454 - "GET /api/social/posts?location_filter=Sigma+Nu HTTP/1.1" 200 OK
INFO:     127.0.0.1:60457 - "GET /api/social/posts?location_filter=Sigma+Nu HTTP/1.1" 200 OK
INFO:     127.0.0.1:60493 - "GET /api/auth/me HTTP/1.1" 200 OK
INFO:     127.0.0.1:60492 - "POST /api/social/user-profile-post/1?location=Kappa%20Sigma HTTP/1.1" 200 OK
INFO:     127.0.0.1:60496 - "GET /api/auth/pickup-locations HTTP/1.1" 200 OK
INFO:     127.0.0.1:60499 - "GET /api/social/posts?location_filter=Kappa+Sigma HTTP/1.1" 200 OK
INFO:     127.0.0.1:60502 - "GET /api/social/posts?location_filter=Kappa+Sigma HTTP/1.1" 200 OK
INFO:     127.0.0.1:60508 - "GET /api/auth/me HTTP/1.1" 200 OK
INFO:     127.0.0.1:60507 - "POST /api/social/user-profile-post/1?location=all HTTP/1.1" 200 OK
INFO:     127.0.0.1:60511 - "GET /api/auth/pickup-locations HTTP/1.1" 200 OK
INFO:     127.0.0.1:60514 - "GET /api/social/posts HTTP/1.1" 500 Internal Server Error
ERROR:    Exception in ASGI application
Traceback (most recent call last):
  File "/Library/Frameworks/Python.framework/Versions/3.12/lib/python3.12/site-packages/uvicorn/protocols/http/httptools_impl.py", line 409, in run_asgi
    result = await app(  # type: ignore[func-returns-value]
             ^^^^^^^^^^^^^^^^^^^^^^^^^^^^^^^^^^^^^^^^^^^^^^
  File "/Library/Frameworks/Python.framework/Versions/3.12/lib/python3.12/site-packages/uvicorn/middleware/proxy_headers.py", line 60, in __call__
    return await self.app(scope, receive, send)
           ^^^^^^^^^^^^^^^^^^^^^^^^^^^^^^^^^^^^
  File "/Library/Frameworks/Python.framework/Versions/3.12/lib/python3.12/site-packages/fastapi/applications.py", line 1054, in __call__
    await super().__call__(scope, receive, send)
  File "/Library/Frameworks/Python.framework/Versions/3.12/lib/python3.12/site-packages/starlette/applications.py", line 112, in __call__
    await self.middleware_stack(scope, receive, send)
  File "/Library/Frameworks/Python.framework/Versions/3.12/lib/python3.12/site-packages/starlette/middleware/errors.py", line 187, in __call__
    raise exc
  File "/Library/Frameworks/Python.framework/Versions/3.12/lib/python3.12/site-packages/starlette/middleware/errors.py", line 165, in __call__
    await self.app(scope, receive, _send)
  File "/Library/Frameworks/Python.framework/Versions/3.12/lib/python3.12/site-packages/starlette/middleware/cors.py", line 85, in __call__
    await self.app(scope, receive, send)
  File "/Library/Frameworks/Python.framework/Versions/3.12/lib/python3.12/site-packages/starlette/middleware/exceptions.py", line 62, in __call__
    await wrap_app_handling_exceptions(self.app, conn)(scope, receive, send)
  File "/Library/Frameworks/Python.framework/Versions/3.12/lib/python3.12/site-packages/starlette/_exception_handler.py", line 53, in wrapped_app
    raise exc
  File "/Library/Frameworks/Python.framework/Versions/3.12/lib/python3.12/site-packages/starlette/_exception_handler.py", line 42, in wrapped_app
    await app(scope, receive, sender)
  File "/Library/Frameworks/Python.framework/Versions/3.12/lib/python3.12/site-packages/starlette/routing.py", line 714, in __call__
    await self.middleware_stack(scope, receive, send)
  File "/Library/Frameworks/Python.framework/Versions/3.12/lib/python3.12/site-packages/starlette/routing.py", line 734, in app
    await route.handle(scope, receive, send)
  File "/Library/Frameworks/Python.framework/Versions/3.12/lib/python3.12/site-packages/starlette/routing.py", line 288, in handle
    await self.app(scope, receive, send)
  File "/Library/Frameworks/Python.framework/Versions/3.12/lib/python3.12/site-packages/starlette/routing.py", line 76, in app
    await wrap_app_handling_exceptions(app, request)(scope, receive, send)
  File "/Library/Frameworks/Python.framework/Versions/3.12/lib/python3.12/site-packages/starlette/_exception_handler.py", line 53, in wrapped_app
    raise exc
  File "/Library/Frameworks/Python.framework/Versions/3.12/lib/python3.12/site-packages/starlette/_exception_handler.py", line 42, in wrapped_app
    await app(scope, receive, sender)
  File "/Library/Frameworks/Python.framework/Versions/3.12/lib/python3.12/site-packages/starlette/routing.py", line 73, in app
    response = await f(request)
               ^^^^^^^^^^^^^^^^
  File "/Library/Frameworks/Python.framework/Versions/3.12/lib/python3.12/site-packages/fastapi/routing.py", line 301, in app
    raw_response = await run_endpoint_function(
                   ^^^^^^^^^^^^^^^^^^^^^^^^^^^^
  File "/Library/Frameworks/Python.framework/Versions/3.12/lib/python3.12/site-packages/fastapi/routing.py", line 212, in run_endpoint_function
    return await dependant.call(**values)
           ^^^^^^^^^^^^^^^^^^^^^^^^^^^^^^
  File "/Users/jackffox/Desktop/street-meat-gatherings-unite/backend/routes/social_feed.py", line 47, in get_posts
    # Add like status for current user
                    ^^^^^^^^^^^^^^^^^^^
  File "/Library/Frameworks/Python.framework/Versions/3.12/lib/python3.12/site-packages/pydantic/main.py", line 627, in model_validate
    return cls.__pydantic_validator__.validate_python(
           ^^^^^^^^^^^^^^^^^^^^^^^^^^^^^^^^^^^^^^^^^^^
pydantic_core._pydantic_core.ValidationError: 4 validation errors for PostWithLikeStatus
comments.0.likes_count
  Error extracting attribute: MissingGreenlet: greenlet_spawn has not been called; can't call await_only() here. Was IO attempted in an unexpected place? (Background on this error at: https://sqlalche.me/e/20/xd2s) [type=get_attribute_error, input_value=<backend.models.Comment object at 0x113b0d250>, input_type=Comment]
    For further information visit https://errors.pydantic.dev/2.10/v/get_attribute_error
comments.0.replies
  Error extracting attribute: MissingGreenlet: greenlet_spawn has not been called; can't call await_only() here. Was IO attempted in an unexpected place? (Background on this error at: https://sqlalche.me/e/20/xd2s) [type=get_attribute_error, input_value=<backend.models.Comment object at 0x113b0d250>, input_type=Comment]
    For further information visit https://errors.pydantic.dev/2.10/v/get_attribute_error
comments.1.likes_count
  Error extracting attribute: MissingGreenlet: greenlet_spawn has not been called; can't call await_only() here. Was IO attempted in an unexpected place? (Background on this error at: https://sqlalche.me/e/20/xd2s) [type=get_attribute_error, input_value=<backend.models.Comment object at 0x113b0d970>, input_type=Comment]
    For further information visit https://errors.pydantic.dev/2.10/v/get_attribute_error
comments.1.replies
  Error extracting attribute: MissingGreenlet: greenlet_spawn has not been called; can't call await_only() here. Was IO attempted in an unexpected place? (Background on this error at: https://sqlalche.me/e/20/xd2s) [type=get_attribute_error, input_value=<backend.models.Comment object at 0x113b0d970>, input_type=Comment]
    For further information visit https://errors.pydantic.dev/2.10/v/get_attribute_error
INFO:     127.0.0.1:60517 - "GET /api/social/posts HTTP/1.1" 500 Internal Server Error
ERROR:    Exception in ASGI application
Traceback (most recent call last):
  File "/Library/Frameworks/Python.framework/Versions/3.12/lib/python3.12/site-packages/uvicorn/protocols/http/httptools_impl.py", line 409, in run_asgi
    result = await app(  # type: ignore[func-returns-value]
             ^^^^^^^^^^^^^^^^^^^^^^^^^^^^^^^^^^^^^^^^^^^^^^
  File "/Library/Frameworks/Python.framework/Versions/3.12/lib/python3.12/site-packages/uvicorn/middleware/proxy_headers.py", line 60, in __call__
    return await self.app(scope, receive, send)
           ^^^^^^^^^^^^^^^^^^^^^^^^^^^^^^^^^^^^
  File "/Library/Frameworks/Python.framework/Versions/3.12/lib/python3.12/site-packages/fastapi/applications.py", line 1054, in __call__
    await super().__call__(scope, receive, send)
  File "/Library/Frameworks/Python.framework/Versions/3.12/lib/python3.12/site-packages/starlette/applications.py", line 112, in __call__
    await self.middleware_stack(scope, receive, send)
  File "/Library/Frameworks/Python.framework/Versions/3.12/lib/python3.12/site-packages/starlette/middleware/errors.py", line 187, in __call__
    raise exc
  File "/Library/Frameworks/Python.framework/Versions/3.12/lib/python3.12/site-packages/starlette/middleware/errors.py", line 165, in __call__
    await self.app(scope, receive, _send)
  File "/Library/Frameworks/Python.framework/Versions/3.12/lib/python3.12/site-packages/starlette/middleware/cors.py", line 85, in __call__
    await self.app(scope, receive, send)
  File "/Library/Frameworks/Python.framework/Versions/3.12/lib/python3.12/site-packages/starlette/middleware/exceptions.py", line 62, in __call__
    await wrap_app_handling_exceptions(self.app, conn)(scope, receive, send)
  File "/Library/Frameworks/Python.framework/Versions/3.12/lib/python3.12/site-packages/starlette/_exception_handler.py", line 53, in wrapped_app
    raise exc
  File "/Library/Frameworks/Python.framework/Versions/3.12/lib/python3.12/site-packages/starlette/_exception_handler.py", line 42, in wrapped_app
    await app(scope, receive, sender)
  File "/Library/Frameworks/Python.framework/Versions/3.12/lib/python3.12/site-packages/starlette/routing.py", line 714, in __call__
    await self.middleware_stack(scope, receive, send)
  File "/Library/Frameworks/Python.framework/Versions/3.12/lib/python3.12/site-packages/starlette/routing.py", line 734, in app
    await route.handle(scope, receive, send)
  File "/Library/Frameworks/Python.framework/Versions/3.12/lib/python3.12/site-packages/starlette/routing.py", line 288, in handle
    await self.app(scope, receive, send)
  File "/Library/Frameworks/Python.framework/Versions/3.12/lib/python3.12/site-packages/starlette/routing.py", line 76, in app
    await wrap_app_handling_exceptions(app, request)(scope, receive, send)
  File "/Library/Frameworks/Python.framework/Versions/3.12/lib/python3.12/site-packages/starlette/_exception_handler.py", line 53, in wrapped_app
    raise exc
  File "/Library/Frameworks/Python.framework/Versions/3.12/lib/python3.12/site-packages/starlette/_exception_handler.py", line 42, in wrapped_app
    await app(scope, receive, sender)
  File "/Library/Frameworks/Python.framework/Versions/3.12/lib/python3.12/site-packages/starlette/routing.py", line 73, in app
    response = await f(request)
               ^^^^^^^^^^^^^^^^
  File "/Library/Frameworks/Python.framework/Versions/3.12/lib/python3.12/site-packages/fastapi/routing.py", line 301, in app
    raw_response = await run_endpoint_function(
                   ^^^^^^^^^^^^^^^^^^^^^^^^^^^^
  File "/Library/Frameworks/Python.framework/Versions/3.12/lib/python3.12/site-packages/fastapi/routing.py", line 212, in run_endpoint_function
    return await dependant.call(**values)
           ^^^^^^^^^^^^^^^^^^^^^^^^^^^^^^
  File "/Users/jackffox/Desktop/street-meat-gatherings-unite/backend/routes/social_feed.py", line 47, in get_posts
    # Add like status for current user
                    ^^^^^^^^^^^^^^^^^^^
  File "/Library/Frameworks/Python.framework/Versions/3.12/lib/python3.12/site-packages/pydantic/main.py", line 627, in model_validate
    return cls.__pydantic_validator__.validate_python(
           ^^^^^^^^^^^^^^^^^^^^^^^^^^^^^^^^^^^^^^^^^^^
pydantic_core._pydantic_core.ValidationError: 4 validation errors for PostWithLikeStatus
comments.0.likes_count
  Error extracting attribute: MissingGreenlet: greenlet_spawn has not been called; can't call await_only() here. Was IO attempted in an unexpected place? (Background on this error at: https://sqlalche.me/e/20/xd2s) [type=get_attribute_error, input_value=<backend.models.Comment object at 0x113b0cf20>, input_type=Comment]
    For further information visit https://errors.pydantic.dev/2.10/v/get_attribute_error
comments.0.replies
  Error extracting attribute: MissingGreenlet: greenlet_spawn has not been called; can't call await_only() here. Was IO attempted in an unexpected place? (Background on this error at: https://sqlalche.me/e/20/xd2s) [type=get_attribute_error, input_value=<backend.models.Comment object at 0x113b0cf20>, input_type=Comment]
    For further information visit https://errors.pydantic.dev/2.10/v/get_attribute_error
comments.1.likes_count
  Error extracting attribute: MissingGreenlet: greenlet_spawn has not been called; can't call await_only() here. Was IO attempted in an unexpected place? (Background on this error at: https://sqlalche.me/e/20/xd2s) [type=get_attribute_error, input_value=<backend.models.Comment object at 0x113b0d970>, input_type=Comment]
    For further information visit https://errors.pydantic.dev/2.10/v/get_attribute_error
comments.1.replies
  Error extracting attribute: MissingGreenlet: greenlet_spawn has not been called; can't call await_only() here. Was IO attempted in an unexpected place? (Background on this error at: https://sqlalche.me/e/20/xd2s) [type=get_attribute_error, input_value=<backend.models.Comment object at 0x113b0d970>, input_type=Comment]
    For further information visit https://errors.pydantic.dev/2.10/v/get_attribute_error
INFO:     127.0.0.1:60524 - "GET /api/auth/me HTTP/1.1" 200 OK
INFO:     127.0.0.1:60523 - "POST /api/social/user-profile-post/1?location=Kappa%20Sigma HTTP/1.1" 200 OK
INFO:     127.0.0.1:60527 - "GET /api/auth/pickup-locations HTTP/1.1" 200 OK
INFO:     127.0.0.1:60530 - "GET /api/social/posts?location_filter=Kappa+Sigma HTTP/1.1" 200 OK
INFO:     127.0.0.1:60533 - "GET /api/social/posts?location_filter=Kappa+Sigma HTTP/1.1" 200 OK
INFO:     127.0.0.1:60537 - "GET /api/auth/me HTTP/1.1" 200 OK
INFO:     127.0.0.1:60540 - "GET /api/auth/pickup-locations HTTP/1.1" 200 OK
INFO:     127.0.0.1:60543 - "GET /api/social/posts?location_filter=Sigma+Nu HTTP/1.1" 200 OK
INFO:     127.0.0.1:60546 - "GET /api/social/posts?location_filter=Sigma+Nu HTTP/1.1" 200 OK
INFO:     127.0.0.1:60553 - "GET /api/auth/me HTTP/1.1" 200 OK
INFO:     127.0.0.1:60556 - "GET /api/auth/pickup-locations HTTP/1.1" 200 OK
INFO:     127.0.0.1:60559 - "GET /api/social/posts?location_filter=White+Plaza HTTP/1.1" 200 OK
INFO:     127.0.0.1:60562 - "GET /api/social/posts?location_filter=White+Plaza HTTP/1.1" 200 OK
INFO:     127.0.0.1:60635 - "GET /api/auth/me HTTP/1.1" 200 OK
INFO:     127.0.0.1:60638 - "GET /api/auth/pickup-locations HTTP/1.1" 200 OK
INFO:     127.0.0.1:60641 - "GET /api/social/posts?location_filter=Sigma+Nu HTTP/1.1" 200 OK
INFO:     127.0.0.1:60644 - "GET /api/social/posts?location_filter=Sigma+Nu HTTP/1.1" 200 OK
INFO:     127.0.0.1:60650 - "GET /api/auth/me HTTP/1.1" 200 OK
INFO:     127.0.0.1:60648 - "POST /api/social/user-profile-post/1?location=Kappa%20Sigma HTTP/1.1" 200 OK
INFO:     127.0.0.1:60653 - "GET /api/auth/pickup-locations HTTP/1.1" 200 OK
INFO:     127.0.0.1:60656 - "GET /api/social/posts?location_filter=Kappa+Sigma HTTP/1.1" 200 OK
INFO:     127.0.0.1:60659 - "GET /api/social/posts?location_filter=Kappa+Sigma HTTP/1.1" 200 OK
INFO:     127.0.0.1:60667 - "GET /api/auth/me HTTP/1.1" 200 OK
INFO:     127.0.0.1:60666 - "POST /api/social/user-profile-post/1?location=all HTTP/1.1" 200 OK
INFO:     127.0.0.1:60670 - "GET /api/auth/pickup-locations HTTP/1.1" 200 OK
INFO:     127.0.0.1:60673 - "GET /api/social/posts HTTP/1.1" 500 Internal Server Error
ERROR:    Exception in ASGI application
Traceback (most recent call last):
  File "/Library/Frameworks/Python.framework/Versions/3.12/lib/python3.12/site-packages/uvicorn/protocols/http/httptools_impl.py", line 409, in run_asgi
    result = await app(  # type: ignore[func-returns-value]
             ^^^^^^^^^^^^^^^^^^^^^^^^^^^^^^^^^^^^^^^^^^^^^^
  File "/Library/Frameworks/Python.framework/Versions/3.12/lib/python3.12/site-packages/uvicorn/middleware/proxy_headers.py", line 60, in __call__
    return await self.app(scope, receive, send)
           ^^^^^^^^^^^^^^^^^^^^^^^^^^^^^^^^^^^^
  File "/Library/Frameworks/Python.framework/Versions/3.12/lib/python3.12/site-packages/fastapi/applications.py", line 1054, in __call__
    await super().__call__(scope, receive, send)
  File "/Library/Frameworks/Python.framework/Versions/3.12/lib/python3.12/site-packages/starlette/applications.py", line 112, in __call__
    await self.middleware_stack(scope, receive, send)
  File "/Library/Frameworks/Python.framework/Versions/3.12/lib/python3.12/site-packages/starlette/middleware/errors.py", line 187, in __call__
    raise exc
  File "/Library/Frameworks/Python.framework/Versions/3.12/lib/python3.12/site-packages/starlette/middleware/errors.py", line 165, in __call__
    await self.app(scope, receive, _send)
  File "/Library/Frameworks/Python.framework/Versions/3.12/lib/python3.12/site-packages/starlette/middleware/cors.py", line 85, in __call__
    await self.app(scope, receive, send)
  File "/Library/Frameworks/Python.framework/Versions/3.12/lib/python3.12/site-packages/starlette/middleware/exceptions.py", line 62, in __call__
    await wrap_app_handling_exceptions(self.app, conn)(scope, receive, send)
  File "/Library/Frameworks/Python.framework/Versions/3.12/lib/python3.12/site-packages/starlette/_exception_handler.py", line 53, in wrapped_app
    raise exc
  File "/Library/Frameworks/Python.framework/Versions/3.12/lib/python3.12/site-packages/starlette/_exception_handler.py", line 42, in wrapped_app
    await app(scope, receive, sender)
  File "/Library/Frameworks/Python.framework/Versions/3.12/lib/python3.12/site-packages/starlette/routing.py", line 714, in __call__
    await self.middleware_stack(scope, receive, send)
  File "/Library/Frameworks/Python.framework/Versions/3.12/lib/python3.12/site-packages/starlette/routing.py", line 734, in app
    await route.handle(scope, receive, send)
  File "/Library/Frameworks/Python.framework/Versions/3.12/lib/python3.12/site-packages/starlette/routing.py", line 288, in handle
    await self.app(scope, receive, send)
  File "/Library/Frameworks/Python.framework/Versions/3.12/lib/python3.12/site-packages/starlette/routing.py", line 76, in app
    await wrap_app_handling_exceptions(app, request)(scope, receive, send)
  File "/Library/Frameworks/Python.framework/Versions/3.12/lib/python3.12/site-packages/starlette/_exception_handler.py", line 53, in wrapped_app
    raise exc
  File "/Library/Frameworks/Python.framework/Versions/3.12/lib/python3.12/site-packages/starlette/_exception_handler.py", line 42, in wrapped_app
    await app(scope, receive, sender)
  File "/Library/Frameworks/Python.framework/Versions/3.12/lib/python3.12/site-packages/starlette/routing.py", line 73, in app
    response = await f(request)
               ^^^^^^^^^^^^^^^^
  File "/Library/Frameworks/Python.framework/Versions/3.12/lib/python3.12/site-packages/fastapi/routing.py", line 301, in app
    raw_response = await run_endpoint_function(
                   ^^^^^^^^^^^^^^^^^^^^^^^^^^^^
  File "/Library/Frameworks/Python.framework/Versions/3.12/lib/python3.12/site-packages/fastapi/routing.py", line 212, in run_endpoint_function
    return await dependant.call(**values)
           ^^^^^^^^^^^^^^^^^^^^^^^^^^^^^^
  File "/Users/jackffox/Desktop/street-meat-gatherings-unite/backend/routes/social_feed.py", line 47, in get_posts
    # Add like status for current user
                    ^^^^^^^^^^^^^^^^^^^
  File "/Library/Frameworks/Python.framework/Versions/3.12/lib/python3.12/site-packages/pydantic/main.py", line 627, in model_validate
    return cls.__pydantic_validator__.validate_python(
           ^^^^^^^^^^^^^^^^^^^^^^^^^^^^^^^^^^^^^^^^^^^
pydantic_core._pydantic_core.ValidationError: 4 validation errors for PostWithLikeStatus
comments.0.likes_count
  Error extracting attribute: MissingGreenlet: greenlet_spawn has not been called; can't call await_only() here. Was IO attempted in an unexpected place? (Background on this error at: https://sqlalche.me/e/20/xd2s) [type=get_attribute_error, input_value=<backend.models.Comment object at 0x113c28740>, input_type=Comment]
    For further information visit https://errors.pydantic.dev/2.10/v/get_attribute_error
comments.0.replies
  Error extracting attribute: MissingGreenlet: greenlet_spawn has not been called; can't call await_only() here. Was IO attempted in an unexpected place? (Background on this error at: https://sqlalche.me/e/20/xd2s) [type=get_attribute_error, input_value=<backend.models.Comment object at 0x113c28740>, input_type=Comment]
    For further information visit https://errors.pydantic.dev/2.10/v/get_attribute_error
comments.1.likes_count
  Error extracting attribute: MissingGreenlet: greenlet_spawn has not been called; can't call await_only() here. Was IO attempted in an unexpected place? (Background on this error at: https://sqlalche.me/e/20/xd2s) [type=get_attribute_error, input_value=<backend.models.Comment object at 0x113c28d40>, input_type=Comment]
    For further information visit https://errors.pydantic.dev/2.10/v/get_attribute_error
comments.1.replies
  Error extracting attribute: MissingGreenlet: greenlet_spawn has not been called; can't call await_only() here. Was IO attempted in an unexpected place? (Background on this error at: https://sqlalche.me/e/20/xd2s) [type=get_attribute_error, input_value=<backend.models.Comment object at 0x113c28d40>, input_type=Comment]
    For further information visit https://errors.pydantic.dev/2.10/v/get_attribute_error
INFO:     127.0.0.1:60676 - "GET /api/social/posts HTTP/1.1" 500 Internal Server Error
ERROR:    Exception in ASGI application
Traceback (most recent call last):
  File "/Library/Frameworks/Python.framework/Versions/3.12/lib/python3.12/site-packages/uvicorn/protocols/http/httptools_impl.py", line 409, in run_asgi
    result = await app(  # type: ignore[func-returns-value]
             ^^^^^^^^^^^^^^^^^^^^^^^^^^^^^^^^^^^^^^^^^^^^^^
  File "/Library/Frameworks/Python.framework/Versions/3.12/lib/python3.12/site-packages/uvicorn/middleware/proxy_headers.py", line 60, in __call__
    return await self.app(scope, receive, send)
           ^^^^^^^^^^^^^^^^^^^^^^^^^^^^^^^^^^^^
  File "/Library/Frameworks/Python.framework/Versions/3.12/lib/python3.12/site-packages/fastapi/applications.py", line 1054, in __call__
    await super().__call__(scope, receive, send)
  File "/Library/Frameworks/Python.framework/Versions/3.12/lib/python3.12/site-packages/starlette/applications.py", line 112, in __call__
    await self.middleware_stack(scope, receive, send)
  File "/Library/Frameworks/Python.framework/Versions/3.12/lib/python3.12/site-packages/starlette/middleware/errors.py", line 187, in __call__
    raise exc
  File "/Library/Frameworks/Python.framework/Versions/3.12/lib/python3.12/site-packages/starlette/middleware/errors.py", line 165, in __call__
    await self.app(scope, receive, _send)
  File "/Library/Frameworks/Python.framework/Versions/3.12/lib/python3.12/site-packages/starlette/middleware/cors.py", line 85, in __call__
    await self.app(scope, receive, send)
  File "/Library/Frameworks/Python.framework/Versions/3.12/lib/python3.12/site-packages/starlette/middleware/exceptions.py", line 62, in __call__
    await wrap_app_handling_exceptions(self.app, conn)(scope, receive, send)
  File "/Library/Frameworks/Python.framework/Versions/3.12/lib/python3.12/site-packages/starlette/_exception_handler.py", line 53, in wrapped_app
    raise exc
  File "/Library/Frameworks/Python.framework/Versions/3.12/lib/python3.12/site-packages/starlette/_exception_handler.py", line 42, in wrapped_app
    await app(scope, receive, sender)
  File "/Library/Frameworks/Python.framework/Versions/3.12/lib/python3.12/site-packages/starlette/routing.py", line 714, in __call__
    await self.middleware_stack(scope, receive, send)
  File "/Library/Frameworks/Python.framework/Versions/3.12/lib/python3.12/site-packages/starlette/routing.py", line 734, in app
    await route.handle(scope, receive, send)
  File "/Library/Frameworks/Python.framework/Versions/3.12/lib/python3.12/site-packages/starlette/routing.py", line 288, in handle
    await self.app(scope, receive, send)
  File "/Library/Frameworks/Python.framework/Versions/3.12/lib/python3.12/site-packages/starlette/routing.py", line 76, in app
    await wrap_app_handling_exceptions(app, request)(scope, receive, send)
  File "/Library/Frameworks/Python.framework/Versions/3.12/lib/python3.12/site-packages/starlette/_exception_handler.py", line 53, in wrapped_app
    raise exc
  File "/Library/Frameworks/Python.framework/Versions/3.12/lib/python3.12/site-packages/starlette/_exception_handler.py", line 42, in wrapped_app
    await app(scope, receive, sender)
  File "/Library/Frameworks/Python.framework/Versions/3.12/lib/python3.12/site-packages/starlette/routing.py", line 73, in app
    response = await f(request)
               ^^^^^^^^^^^^^^^^
  File "/Library/Frameworks/Python.framework/Versions/3.12/lib/python3.12/site-packages/fastapi/routing.py", line 301, in app
    raw_response = await run_endpoint_function(
                   ^^^^^^^^^^^^^^^^^^^^^^^^^^^^
  File "/Library/Frameworks/Python.framework/Versions/3.12/lib/python3.12/site-packages/fastapi/routing.py", line 212, in run_endpoint_function
    return await dependant.call(**values)
           ^^^^^^^^^^^^^^^^^^^^^^^^^^^^^^
  File "/Users/jackffox/Desktop/street-meat-gatherings-unite/backend/routes/social_feed.py", line 47, in get_posts
    # Add like status for current user
                    ^^^^^^^^^^^^^^^^^^^
  File "/Library/Frameworks/Python.framework/Versions/3.12/lib/python3.12/site-packages/pydantic/main.py", line 627, in model_validate
    return cls.__pydantic_validator__.validate_python(
           ^^^^^^^^^^^^^^^^^^^^^^^^^^^^^^^^^^^^^^^^^^^
pydantic_core._pydantic_core.ValidationError: 4 validation errors for PostWithLikeStatus
comments.0.likes_count
  Error extracting attribute: MissingGreenlet: greenlet_spawn has not been called; can't call await_only() here. Was IO attempted in an unexpected place? (Background on this error at: https://sqlalche.me/e/20/xd2s) [type=get_attribute_error, input_value=<backend.models.Comment object at 0x113c62c30>, input_type=Comment]
    For further information visit https://errors.pydantic.dev/2.10/v/get_attribute_error
comments.0.replies
  Error extracting attribute: MissingGreenlet: greenlet_spawn has not been called; can't call await_only() here. Was IO attempted in an unexpected place? (Background on this error at: https://sqlalche.me/e/20/xd2s) [type=get_attribute_error, input_value=<backend.models.Comment object at 0x113c62c30>, input_type=Comment]
    For further information visit https://errors.pydantic.dev/2.10/v/get_attribute_error
comments.1.likes_count
  Error extracting attribute: MissingGreenlet: greenlet_spawn has not been called; can't call await_only() here. Was IO attempted in an unexpected place? (Background on this error at: https://sqlalche.me/e/20/xd2s) [type=get_attribute_error, input_value=<backend.models.Comment object at 0x113c63d70>, input_type=Comment]
    For further information visit https://errors.pydantic.dev/2.10/v/get_attribute_error
comments.1.replies
  Error extracting attribute: MissingGreenlet: greenlet_spawn has not been called; can't call await_only() here. Was IO attempted in an unexpected place? (Background on this error at: https://sqlalche.me/e/20/xd2s) [type=get_attribute_error, input_value=<backend.models.Comment object at 0x113c63d70>, input_type=Comment]
    For further information visit https://errors.pydantic.dev/2.10/v/get_attribute_error
INFO:     127.0.0.1:60685 - "GET /api/auth/me HTTP/1.1" 200 OK
INFO:     127.0.0.1:60684 - "POST /api/social/user-profile-post/1?location=Kappa%20Sigma HTTP/1.1" 200 OK
INFO:     127.0.0.1:60688 - "GET /api/auth/pickup-locations HTTP/1.1" 200 OK
INFO:     127.0.0.1:60691 - "GET /api/social/posts?location_filter=Kappa+Sigma HTTP/1.1" 200 OK
INFO:     127.0.0.1:60694 - "GET /api/social/posts?location_filter=Kappa+Sigma HTTP/1.1" 200 OK
INFO:     127.0.0.1:60698 - "GET /api/auth/me HTTP/1.1" 200 OK
INFO:     127.0.0.1:60701 - "GET /api/auth/pickup-locations HTTP/1.1" 200 OK
INFO:     127.0.0.1:60704 - "GET /api/social/posts?location_filter=Sigma+Nu HTTP/1.1" 200 OK
INFO:     127.0.0.1:60707 - "GET /api/social/posts?location_filter=Sigma+Nu HTTP/1.1" 200 OK
INFO:     127.0.0.1:60711 - "GET /api/auth/me HTTP/1.1" 200 OK
INFO:     127.0.0.1:60714 - "GET /api/auth/pickup-locations HTTP/1.1" 200 OK
INFO:     127.0.0.1:60717 - "GET /api/social/posts?location_filter=White+Plaza HTTP/1.1" 200 OK
INFO:     127.0.0.1:60720 - "GET /api/social/posts?location_filter=White+Plaza HTTP/1.1" 200 OK
INFO:     127.0.0.1:60723 - "GET /api/auth/me HTTP/1.1" 200 OK
INFO:     127.0.0.1:60726 - "GET /api/auth/pickup-locations HTTP/1.1" 200 OK
INFO:     127.0.0.1:60729 - "GET /api/social/posts?location_filter=Sigma+Nu HTTP/1.1" 200 OK
INFO:     127.0.0.1:60732 - "GET /api/social/posts?location_filter=Sigma+Nu HTTP/1.1" 200 OK
INFO:     127.0.0.1:60739 - "GET /api/auth/me HTTP/1.1" 200 OK
INFO:     127.0.0.1:60738 - "POST /api/social/user-profile-post/1?location=Kappa%20Sigma HTTP/1.1" 200 OK
INFO:     127.0.0.1:60742 - "GET /api/auth/pickup-locations HTTP/1.1" 200 OK
INFO:     127.0.0.1:60745 - "GET /api/social/posts?location_filter=Kappa+Sigma HTTP/1.1" 200 OK
INFO:     127.0.0.1:60748 - "GET /api/social/posts?location_filter=Kappa+Sigma HTTP/1.1" 200 OK
INFO:     127.0.0.1:60754 - "GET /api/auth/me HTTP/1.1" 200 OK
INFO:     127.0.0.1:60753 - "POST /api/social/user-profile-post/1?location=all HTTP/1.1" 200 OK
INFO:     127.0.0.1:60757 - "GET /api/auth/pickup-locations HTTP/1.1" 200 OK
INFO:     127.0.0.1:60760 - "GET /api/social/posts HTTP/1.1" 500 Internal Server Error
ERROR:    Exception in ASGI application
Traceback (most recent call last):
  File "/Library/Frameworks/Python.framework/Versions/3.12/lib/python3.12/site-packages/uvicorn/protocols/http/httptools_impl.py", line 409, in run_asgi
    result = await app(  # type: ignore[func-returns-value]
             ^^^^^^^^^^^^^^^^^^^^^^^^^^^^^^^^^^^^^^^^^^^^^^
  File "/Library/Frameworks/Python.framework/Versions/3.12/lib/python3.12/site-packages/uvicorn/middleware/proxy_headers.py", line 60, in __call__
    return await self.app(scope, receive, send)
           ^^^^^^^^^^^^^^^^^^^^^^^^^^^^^^^^^^^^
  File "/Library/Frameworks/Python.framework/Versions/3.12/lib/python3.12/site-packages/fastapi/applications.py", line 1054, in __call__
    await super().__call__(scope, receive, send)
  File "/Library/Frameworks/Python.framework/Versions/3.12/lib/python3.12/site-packages/starlette/applications.py", line 112, in __call__
    await self.middleware_stack(scope, receive, send)
  File "/Library/Frameworks/Python.framework/Versions/3.12/lib/python3.12/site-packages/starlette/middleware/errors.py", line 187, in __call__
    raise exc
  File "/Library/Frameworks/Python.framework/Versions/3.12/lib/python3.12/site-packages/starlette/middleware/errors.py", line 165, in __call__
    await self.app(scope, receive, _send)
  File "/Library/Frameworks/Python.framework/Versions/3.12/lib/python3.12/site-packages/starlette/middleware/cors.py", line 85, in __call__
    await self.app(scope, receive, send)
  File "/Library/Frameworks/Python.framework/Versions/3.12/lib/python3.12/site-packages/starlette/middleware/exceptions.py", line 62, in __call__
    await wrap_app_handling_exceptions(self.app, conn)(scope, receive, send)
  File "/Library/Frameworks/Python.framework/Versions/3.12/lib/python3.12/site-packages/starlette/_exception_handler.py", line 53, in wrapped_app
    raise exc
  File "/Library/Frameworks/Python.framework/Versions/3.12/lib/python3.12/site-packages/starlette/_exception_handler.py", line 42, in wrapped_app
    await app(scope, receive, sender)
  File "/Library/Frameworks/Python.framework/Versions/3.12/lib/python3.12/site-packages/starlette/routing.py", line 714, in __call__
    await self.middleware_stack(scope, receive, send)
  File "/Library/Frameworks/Python.framework/Versions/3.12/lib/python3.12/site-packages/starlette/routing.py", line 734, in app
    await route.handle(scope, receive, send)
  File "/Library/Frameworks/Python.framework/Versions/3.12/lib/python3.12/site-packages/starlette/routing.py", line 288, in handle
    await self.app(scope, receive, send)
  File "/Library/Frameworks/Python.framework/Versions/3.12/lib/python3.12/site-packages/starlette/routing.py", line 76, in app
    await wrap_app_handling_exceptions(app, request)(scope, receive, send)
  File "/Library/Frameworks/Python.framework/Versions/3.12/lib/python3.12/site-packages/starlette/_exception_handler.py", line 53, in wrapped_app
    raise exc
  File "/Library/Frameworks/Python.framework/Versions/3.12/lib/python3.12/site-packages/starlette/_exception_handler.py", line 42, in wrapped_app
    await app(scope, receive, sender)
  File "/Library/Frameworks/Python.framework/Versions/3.12/lib/python3.12/site-packages/starlette/routing.py", line 73, in app
    response = await f(request)
               ^^^^^^^^^^^^^^^^
  File "/Library/Frameworks/Python.framework/Versions/3.12/lib/python3.12/site-packages/fastapi/routing.py", line 301, in app
    raw_response = await run_endpoint_function(
                   ^^^^^^^^^^^^^^^^^^^^^^^^^^^^
  File "/Library/Frameworks/Python.framework/Versions/3.12/lib/python3.12/site-packages/fastapi/routing.py", line 212, in run_endpoint_function
    return await dependant.call(**values)
           ^^^^^^^^^^^^^^^^^^^^^^^^^^^^^^
  File "/Users/jackffox/Desktop/street-meat-gatherings-unite/backend/routes/social_feed.py", line 47, in get_posts
    # Add like status for current user
                    ^^^^^^^^^^^^^^^^^^^
  File "/Library/Frameworks/Python.framework/Versions/3.12/lib/python3.12/site-packages/pydantic/main.py", line 627, in model_validate
    return cls.__pydantic_validator__.validate_python(
           ^^^^^^^^^^^^^^^^^^^^^^^^^^^^^^^^^^^^^^^^^^^
pydantic_core._pydantic_core.ValidationError: 4 validation errors for PostWithLikeStatus
comments.0.likes_count
  Error extracting attribute: MissingGreenlet: greenlet_spawn has not been called; can't call await_only() here. Was IO attempted in an unexpected place? (Background on this error at: https://sqlalche.me/e/20/xd2s) [type=get_attribute_error, input_value=<backend.models.Comment object at 0x113c2afc0>, input_type=Comment]
    For further information visit https://errors.pydantic.dev/2.10/v/get_attribute_error
comments.0.replies
  Error extracting attribute: MissingGreenlet: greenlet_spawn has not been called; can't call await_only() here. Was IO attempted in an unexpected place? (Background on this error at: https://sqlalche.me/e/20/xd2s) [type=get_attribute_error, input_value=<backend.models.Comment object at 0x113c2afc0>, input_type=Comment]
    For further information visit https://errors.pydantic.dev/2.10/v/get_attribute_error
comments.1.likes_count
  Error extracting attribute: MissingGreenlet: greenlet_spawn has not been called; can't call await_only() here. Was IO attempted in an unexpected place? (Background on this error at: https://sqlalche.me/e/20/xd2s) [type=get_attribute_error, input_value=<backend.models.Comment object at 0x113c2ab40>, input_type=Comment]
    For further information visit https://errors.pydantic.dev/2.10/v/get_attribute_error
comments.1.replies
  Error extracting attribute: MissingGreenlet: greenlet_spawn has not been called; can't call await_only() here. Was IO attempted in an unexpected place? (Background on this error at: https://sqlalche.me/e/20/xd2s) [type=get_attribute_error, input_value=<backend.models.Comment object at 0x113c2ab40>, input_type=Comment]
    For further information visit https://errors.pydantic.dev/2.10/v/get_attribute_error
INFO:     127.0.0.1:60763 - "GET /api/social/posts HTTP/1.1" 500 Internal Server Error
ERROR:    Exception in ASGI application
Traceback (most recent call last):
  File "/Library/Frameworks/Python.framework/Versions/3.12/lib/python3.12/site-packages/uvicorn/protocols/http/httptools_impl.py", line 409, in run_asgi
    result = await app(  # type: ignore[func-returns-value]
             ^^^^^^^^^^^^^^^^^^^^^^^^^^^^^^^^^^^^^^^^^^^^^^
  File "/Library/Frameworks/Python.framework/Versions/3.12/lib/python3.12/site-packages/uvicorn/middleware/proxy_headers.py", line 60, in __call__
    return await self.app(scope, receive, send)
           ^^^^^^^^^^^^^^^^^^^^^^^^^^^^^^^^^^^^
  File "/Library/Frameworks/Python.framework/Versions/3.12/lib/python3.12/site-packages/fastapi/applications.py", line 1054, in __call__
    await super().__call__(scope, receive, send)
  File "/Library/Frameworks/Python.framework/Versions/3.12/lib/python3.12/site-packages/starlette/applications.py", line 112, in __call__
    await self.middleware_stack(scope, receive, send)
  File "/Library/Frameworks/Python.framework/Versions/3.12/lib/python3.12/site-packages/starlette/middleware/errors.py", line 187, in __call__
    raise exc
  File "/Library/Frameworks/Python.framework/Versions/3.12/lib/python3.12/site-packages/starlette/middleware/errors.py", line 165, in __call__
    await self.app(scope, receive, _send)
  File "/Library/Frameworks/Python.framework/Versions/3.12/lib/python3.12/site-packages/starlette/middleware/cors.py", line 85, in __call__
    await self.app(scope, receive, send)
  File "/Library/Frameworks/Python.framework/Versions/3.12/lib/python3.12/site-packages/starlette/middleware/exceptions.py", line 62, in __call__
    await wrap_app_handling_exceptions(self.app, conn)(scope, receive, send)
  File "/Library/Frameworks/Python.framework/Versions/3.12/lib/python3.12/site-packages/starlette/_exception_handler.py", line 53, in wrapped_app
    raise exc
  File "/Library/Frameworks/Python.framework/Versions/3.12/lib/python3.12/site-packages/starlette/_exception_handler.py", line 42, in wrapped_app
    await app(scope, receive, sender)
  File "/Library/Frameworks/Python.framework/Versions/3.12/lib/python3.12/site-packages/starlette/routing.py", line 714, in __call__
    await self.middleware_stack(scope, receive, send)
  File "/Library/Frameworks/Python.framework/Versions/3.12/lib/python3.12/site-packages/starlette/routing.py", line 734, in app
    await route.handle(scope, receive, send)
  File "/Library/Frameworks/Python.framework/Versions/3.12/lib/python3.12/site-packages/starlette/routing.py", line 288, in handle
    await self.app(scope, receive, send)
  File "/Library/Frameworks/Python.framework/Versions/3.12/lib/python3.12/site-packages/starlette/routing.py", line 76, in app
    await wrap_app_handling_exceptions(app, request)(scope, receive, send)
  File "/Library/Frameworks/Python.framework/Versions/3.12/lib/python3.12/site-packages/starlette/_exception_handler.py", line 53, in wrapped_app
    raise exc
  File "/Library/Frameworks/Python.framework/Versions/3.12/lib/python3.12/site-packages/starlette/_exception_handler.py", line 42, in wrapped_app
    await app(scope, receive, sender)
  File "/Library/Frameworks/Python.framework/Versions/3.12/lib/python3.12/site-packages/starlette/routing.py", line 73, in app
    response = await f(request)
               ^^^^^^^^^^^^^^^^
  File "/Library/Frameworks/Python.framework/Versions/3.12/lib/python3.12/site-packages/fastapi/routing.py", line 301, in app
    raw_response = await run_endpoint_function(
                   ^^^^^^^^^^^^^^^^^^^^^^^^^^^^
  File "/Library/Frameworks/Python.framework/Versions/3.12/lib/python3.12/site-packages/fastapi/routing.py", line 212, in run_endpoint_function
    return await dependant.call(**values)
           ^^^^^^^^^^^^^^^^^^^^^^^^^^^^^^
  File "/Users/jackffox/Desktop/street-meat-gatherings-unite/backend/routes/social_feed.py", line 47, in get_posts
    # Add like status for current user
                    ^^^^^^^^^^^^^^^^^^^
  File "/Library/Frameworks/Python.framework/Versions/3.12/lib/python3.12/site-packages/pydantic/main.py", line 627, in model_validate
    return cls.__pydantic_validator__.validate_python(
           ^^^^^^^^^^^^^^^^^^^^^^^^^^^^^^^^^^^^^^^^^^^
pydantic_core._pydantic_core.ValidationError: 4 validation errors for PostWithLikeStatus
comments.0.likes_count
  Error extracting attribute: MissingGreenlet: greenlet_spawn has not been called; can't call await_only() here. Was IO attempted in an unexpected place? (Background on this error at: https://sqlalche.me/e/20/xd2s) [type=get_attribute_error, input_value=<backend.models.Comment object at 0x113c63020>, input_type=Comment]
    For further information visit https://errors.pydantic.dev/2.10/v/get_attribute_error
comments.0.replies
  Error extracting attribute: MissingGreenlet: greenlet_spawn has not been called; can't call await_only() here. Was IO attempted in an unexpected place? (Background on this error at: https://sqlalche.me/e/20/xd2s) [type=get_attribute_error, input_value=<backend.models.Comment object at 0x113c63020>, input_type=Comment]
    For further information visit https://errors.pydantic.dev/2.10/v/get_attribute_error
comments.1.likes_count
  Error extracting attribute: MissingGreenlet: greenlet_spawn has not been called; can't call await_only() here. Was IO attempted in an unexpected place? (Background on this error at: https://sqlalche.me/e/20/xd2s) [type=get_attribute_error, input_value=<backend.models.Comment object at 0x113c615e0>, input_type=Comment]
    For further information visit https://errors.pydantic.dev/2.10/v/get_attribute_error
comments.1.replies
  Error extracting attribute: MissingGreenlet: greenlet_spawn has not been called; can't call await_only() here. Was IO attempted in an unexpected place? (Background on this error at: https://sqlalche.me/e/20/xd2s) [type=get_attribute_error, input_value=<backend.models.Comment object at 0x113c615e0>, input_type=Comment]
    For further information visit https://errors.pydantic.dev/2.10/v/get_attribute_error
